<!-- vis_lecture/xacro/basic5_h.xacro -->
<robot xmlns:xacro="http://ros.org/wiki/xacro">
  <xacro:property name="M_SCALE" value="0.001"/>
  <xacro:include filename="$(find scara_arm)/urdf/hardware.xacro" />
  
    <!-- side reflect parent -->
  <xacro:macro name="gripper_macro" params="parent">
  
   <joint name="gripper_joint_base" type="fixed">
    	<parent link="${parent}" />
    	<child link="gripper_base" />  
        <origin rpy="1.57 0 0" xyz="0.04 0 0"/>  
  </joint>
   <xacro:my_box name="gripper_base" lwh="0.06 0.03 0.01" xyz="0 0 0" rpy="0 0 0" mass="0.1" material="Gazebo/FlatBlack">
     <xacro:gold />
  </xacro:my_box>


<joint name="gripper" type="revolute">
    	<parent link="gripper_base" />
    	<child link="right_claw" />
        <origin xyz="0.07 0 0 " rpy="-1.57 -1.57 0" />
    	<axis xyz="0 0 1" />
    	<limit lower="-1.3" upper="0.0" effort="10" velocity="10" />
      	<dynamics damping="0.0"/>
	</joint>

   <link name="right_claw" >
   <visual>
      <geometry>
        <mesh filename="package://scara_arm/mesh/claw_3_rr.stl" scale="${M_SCALE} ${M_SCALE} ${M_SCALE}"/>
      </geometry>
         <xacro:White/>
      <origin rpy="0 0 0" xyz="0 0 0"/>
    </visual>
   <collision>
        <origin xyz="0 0 0" rpy="0 0 0" />
        <geometry>
          <mesh filename="package://scara_arm/mesh/claw_3_rr.stl" scale="${M_SCALE} ${M_SCALE} ${M_SCALE}"/>
          </geometry>
      </collision>
  </link>

<joint name="gripper_finger_joint2" type="revolute">
    	<parent link="gripper_base" />
    	<child link="left_claw" />
        <origin xyz="0.07 0 0 " rpy="-1.57 -1.57 0" />
    	<axis xyz="0 0 1" />
    	<limit lower="-0.64" upper="0.0" effort="10" velocity="1" />
        <mimic joint="gripper" multiplier="-1" offset="0"/>
      	<dynamics damping="0.0"/>
	</joint>

   <link name="left_claw" >
   <visual>
      <geometry>
        <mesh filename="package://scara_arm/mesh/claw_3_l.stl" scale="${M_SCALE} ${M_SCALE} ${M_SCALE}"/>
      </geometry>
         <xacro:White/>
      <origin rpy="0 0 0" xyz="0 0 0"/>
    </visual>
   <collision>
        <origin xyz="0 0 0" rpy="0 0 0" />
        <geometry>
          <mesh filename="package://scara_arm/mesh/claw_3_l.stl" scale="${M_SCALE} ${M_SCALE} ${M_SCALE}"/>
          </geometry>
      </collision>
  </link>

<!-- Fake gripper link and joint for grasp planning -->
    <joint name="gripper_link" type="fixed">
      <origin xyz="0 0.03 0" rpy="3.14 0 1.57"/>
      <parent link="right_claw"/>
      <child link="gripper_link"/>
    </joint>
    <link name="gripper_link">
      
    </link>
  </xacro:macro>
</robot>
